<robot name = "robot">
    <link name="Torso">
        <inertial>
            <origin xyz="0.0 0.0 2.0" rpy="0 0 0"/>
            <mass value="10" />
            <inertia ixx="100" ixy="0" ixz="0" iyy="100" iyz="0" izz="100" />
        </inertial>
        <visual>
            <origin xyz="0.0 0.0 2.0" rpy="0 0 0"/>
            <geometry>
                <box size="1.7 1.0 0.5" />
            </geometry>
            <material name="Cyan">
                <color rgba="0 1.0 1.0 1.0"/>
            </material>
        </visual>
        <collision>
            <origin xyz="0.0 0.0 2.0" rpy="0 0 0"/>
            <geometry>
                <box size="1.7 1.0 0.5" />
            </geometry>
        </collision>
    </link>
    <joint name="Torso_Leg1A" type="revolute">
       <parent link="Torso"/>
       <child  link="Leg1A"/>
       <origin rpy="0 0 0" xyz="0.5 0.5 2.0" />
     <axis xyz="1 1 0"/>
       <limit effort="0.0" lower="-3.14159" upper="3.14159" velocity="0.0"/>
    </joint>
    <link name="Leg1A">
        <inertial>
            <origin xyz="0.0 0.0 -0.5" rpy="0 0 0"/>
            <mass value="10" />
            <inertia ixx="100" ixy="0" ixz="0" iyy="100" iyz="0" izz="100" />
        </inertial>
        <visual>
            <origin xyz="0.0 0.0 -0.5" rpy="0 0 0"/>
            <geometry>
                <box size="0.3 0.3 1.0" />
            </geometry>
            <material name="Cyan">
                <color rgba="0 1.0 1.0 1.0"/>
            </material>
        </visual>
        <collision>
            <origin xyz="0.0 0.0 -0.5" rpy="0 0 0"/>
            <geometry>
                <box size="0.3 0.3 1.0" />
            </geometry>
        </collision>
    </link>
    <joint name="Leg1A_Leg1B" type="revolute">
       <parent link="Leg1A"/>
       <child  link="Leg1B"/>
       <origin rpy="0 0 0" xyz="0.0 0.0 -1.0" />
     <axis xyz="0 1 0"/>
       <limit effort="0.0" lower="-3.14159" upper="3.14159" velocity="0.0"/>
    </joint>
    <link name="Leg1B">
        <inertial>
            <origin xyz="0.0 0.0 -0.5" rpy="0 0 0"/>
            <mass value="10" />
            <inertia ixx="100" ixy="0" ixz="0" iyy="100" iyz="0" izz="100" />
        </inertial>
        <visual>
            <origin xyz="0.0 0.0 -0.5" rpy="0 0 0"/>
            <geometry>
                <box size="0.3 0.3 1.0" />
            </geometry>
            <material name="Cyan">
                <color rgba="0 1.0 1.0 1.0"/>
            </material>
        </visual>
        <collision>
            <origin xyz="0.0 0.0 -0.5" rpy="0 0 0"/>
            <geometry>
                <box size="0.3 0.3 1.0" />
            </geometry>
        </collision>
    </link>
    <joint name="Torso_Leg2A" type="revolute">
       <parent link="Torso"/>
       <child  link="Leg2A"/>
       <origin rpy="0 0 0" xyz="-0.5 0.5 2.0" />
     <axis xyz="1 1 0"/>
       <limit effort="0.0" lower="-3.14159" upper="3.14159" velocity="0.0"/>
    </joint>
    <link name="Leg2A">
        <inertial>
            <origin xyz="0.0 0.0 -0.5" rpy="0 0 0"/>
            <mass value="10" />
            <inertia ixx="100" ixy="0" ixz="0" iyy="100" iyz="0" izz="100" />
        </inertial>
        <visual>
            <origin xyz="0.0 0.0 -0.5" rpy="0 0 0"/>
            <geometry>
                <box size="0.3 0.3 1.0" />
            </geometry>
            <material name="Cyan">
                <color rgba="0 1.0 1.0 1.0"/>
            </material>
        </visual>
        <collision>
            <origin xyz="0.0 0.0 -0.5" rpy="0 0 0"/>
            <geometry>
                <box size="0.3 0.3 1.0" />
            </geometry>
        </collision>
    </link>
    <joint name="Leg2A_Leg2B" type="revolute">
       <parent link="Leg2A"/>
       <child  link="Leg2B"/>
       <origin rpy="0 0 0" xyz="0.0 0.0 -1.0" />
     <axis xyz="0 1 0"/>
       <limit effort="0.0" lower="-3.14159" upper="3.14159" velocity="0.0"/>
    </joint>
    <link name="Leg2B">
        <inertial>
            <origin xyz="0.0 0.0 -0.5" rpy="0 0 0"/>
            <mass value="10" />
            <inertia ixx="100" ixy="0" ixz="0" iyy="100" iyz="0" izz="100" />
        </inertial>
        <visual>
            <origin xyz="0.0 0.0 -0.5" rpy="0 0 0"/>
            <geometry>
                <box size="0.3 0.3 1.0" />
            </geometry>
            <material name="Cyan">
                <color rgba="0 1.0 1.0 1.0"/>
            </material>
        </visual>
        <collision>
            <origin xyz="0.0 0.0 -0.5" rpy="0 0 0"/>
            <geometry>
                <box size="0.3 0.3 1.0" />
            </geometry>
        </collision>
    </link>
    <joint name="Torso_Leg3A" type="revolute">
       <parent link="Torso"/>
       <child  link="Leg3A"/>
       <origin rpy="0 0 0" xyz="0.5 -0.5 2.0" />
     <axis xyz="1 1 0"/>
       <limit effort="0.0" lower="-3.14159" upper="3.14159" velocity="0.0"/>
    </joint>
    <link name="Leg3A">
        <inertial>
            <origin xyz="0.0 0.0 -0.5" rpy="0 0 0"/>
            <mass value="10" />
            <inertia ixx="100" ixy="0" ixz="0" iyy="100" iyz="0" izz="100" />
        </inertial>
        <visual>
            <origin xyz="0.0 0.0 -0.5" rpy="0 0 0"/>
            <geometry>
                <box size="0.3 0.3 1.0" />
            </geometry>
            <material name="Cyan">
                <color rgba="0 1.0 1.0 1.0"/>
            </material>
        </visual>
        <collision>
            <origin xyz="0.0 0.0 -0.5" rpy="0 0 0"/>
            <geometry>
                <box size="0.3 0.3 1.0" />
            </geometry>
        </collision>
    </link>
    <joint name="Leg3A_Leg3B" type="revolute">
       <parent link="Leg3A"/>
       <child  link="Leg3B"/>
       <origin rpy="0 0 0" xyz="0.0 0 -1.0" />
     <axis xyz="0 1 0"/>
       <limit effort="0.0" lower="-3.14159" upper="3.14159" velocity="0.0"/>
    </joint>
    <link name="Leg3B">
        <inertial>
            <origin xyz="0.0 0.0 -0.5" rpy="0 0 0"/>
            <mass value="10" />
            <inertia ixx="100" ixy="0" ixz="0" iyy="100" iyz="0" izz="100" />
        </inertial>
        <visual>
            <origin xyz="0.0 0.0 -0.5" rpy="0 0 0"/>
            <geometry>
                <box size="0.3 0.3 1.0" />
            </geometry>
            <material name="Cyan">
                <color rgba="0 1.0 1.0 1.0"/>
            </material>
        </visual>
        <collision>
            <origin xyz="0.0 0.0 -0.5" rpy="0 0 0"/>
            <geometry>
                <box size="0.3 0.3 1.0" />
            </geometry>
        </collision>
    </link>
    <joint name="Torso_Leg4A" type="revolute">
       <parent link="Torso"/>
       <child  link="Leg4A"/>
       <origin rpy="0 0 0" xyz="-0.5 -0.5 2.0" />
     <axis xyz="1 1 0"/>
       <limit effort="0.0" lower="-3.14159" upper="3.14159" velocity="0.0"/>
    </joint>
    <link name="Leg4A">
        <inertial>
            <origin xyz="0.0 0.0 -0.5" rpy="0 0 0"/>
            <mass value="10" />
            <inertia ixx="100" ixy="0" ixz="0" iyy="100" iyz="0" izz="100" />
        </inertial>
        <visual>
            <origin xyz="0.0 0.0 -0.5" rpy="0 0 0"/>
            <geometry>
                <box size="0.3 0.3 1.0" />
            </geometry>
            <material name="Cyan">
                <color rgba="0 1.0 1.0 1.0"/>
            </material>
        </visual>
        <collision>
            <origin xyz="0.0 0.0 -0.5" rpy="0 0 0"/>
            <geometry>
                <box size="0.3 0.3 1.0" />
            </geometry>
        </collision>
    </link>
    <joint name="Leg4A_Leg4B" type="revolute">
       <parent link="Leg4A"/>
       <child  link="Leg4B"/>
       <origin rpy="0 0 0" xyz="0.0 0.0 -1.0" />
     <axis xyz="0 1 0"/>
       <limit effort="0.0" lower="-3.14159" upper="3.14159" velocity="0.0"/>
    </joint>
    <link name="Leg4B">
        <inertial>
            <origin xyz="0.0 0.0 -0.5" rpy="0 0 0"/>
            <mass value="10" />
            <inertia ixx="100" ixy="0" ixz="0" iyy="100" iyz="0" izz="100" />
        </inertial>
        <visual>
            <origin xyz="0.0 0.0 -0.5" rpy="0 0 0"/>
            <geometry>
                <box size="0.3 0.3 1.0" />
            </geometry>
            <material name="Cyan">
                <color rgba="0 1.0 1.0 1.0"/>
            </material>
        </visual>
        <collision>
            <origin xyz="0.0 0.0 -0.5" rpy="0 0 0"/>
            <geometry>
                <box size="0.3 0.3 1.0" />
            </geometry>
        </collision>
    </link>
    <joint name="Torso_Rod1" type="revolute">
       <parent link="Torso"/>
       <child  link="Rod1"/>
       <origin rpy="0 0 0" xyz="0.5 0.0 2.25" />
     <axis xyz="0 1 0"/>
       <limit effort="0.0" lower="-3.14159" upper="3.14159" velocity="0.0"/>
    </joint>
    <link name="Rod1">
        <inertial>
            <origin xyz="0.0 0.0 0.3" rpy="0 0 0"/>
            <mass value="10" />
            <inertia ixx="100" ixy="0" ixz="0" iyy="100" iyz="0" izz="100" />
        </inertial>
        <visual>
            <origin xyz="0.0 0.0 0.3" rpy="0 0 0"/>
            <geometry>
                <box size="0.3 0.3 0.6" />
            </geometry>
            <material name="Cyan">
                <color rgba="0 1.0 1.0 1.0"/>
            </material>
        </visual>
        <collision>
            <origin xyz="0.0 0.0 0.3" rpy="0 0 0"/>
            <geometry>
                <box size="0.3 0.3 0.6" />
            </geometry>
        </collision>
    </link>
    <joint name="Rod1_Rod2" type="revolute">
       <parent link="Rod1"/>
       <child  link="Rod2"/>
       <origin rpy="0 0 0" xyz="0.0 0.0 0.6" />
     <axis xyz="0 1 0"/>
       <limit effort="0.0" lower="-3.14159" upper="3.14159" velocity="0.0"/>
    </joint>
    <link name="Rod2">
        <inertial>
            <origin xyz="0.3 0.0 0" rpy="0 0 0"/>
            <mass value="10" />
            <inertia ixx="100" ixy="0" ixz="0" iyy="100" iyz="0" izz="100" />
        </inertial>
        <visual>
            <origin xyz="0.3 0.0 0" rpy="0 0 0"/>
            <geometry>
                <box size="0.6 0.3 0.3" />
            </geometry>
            <material name="Cyan">
                <color rgba="0 1.0 1.0 1.0"/>
            </material>
        </visual>
        <collision>
            <origin xyz="0.3 0.0 0" rpy="0 0 0"/>
            <geometry>
                <box size="0.6 0.3 0.3" />
            </geometry>
        </collision>
    </link>
</robot>